WARNING:torch.distributed.run:
*****************************************
Setting OMP_NUM_THREADS environment variable for each process to be 1 in default, to avoid your system being overloaded, please further tune the variable for optimal performance in your application as needed. 
*****************************************
/home/ckq/anaconda3/envs/py39/bin/python: can't open file '/train/train_mem.py': [Errno 2] No such file or directory
/home/ckq/anaconda3/envs/py39/bin/python: can't open file '/train/train_mem.py': [Errno 2] No such file or directory
/home/ckq/anaconda3/envs/py39/bin/python: can't open file '/train/train_mem.py': [Errno 2] No such file or directory
/home/ckq/anaconda3/envs/py39/bin/python: can't open file '/train/train_mem.py': [Errno 2] No such file or directory
/home/ckq/anaconda3/envs/py39/bin/python: can't open file '/train/train_mem.py': [Errno 2] No such file or directory
/home/ckq/anaconda3/envs/py39/bin/python: can't open file '/train/train_mem.py': [Errno 2] No such file or directory
ERROR:torch.distributed.elastic.multiprocessing.api:failed (exitcode: 2) local_rank: 0 (pid: 2387745) of binary: /home/ckq/anaconda3/envs/py39/bin/python
Traceback (most recent call last):
  File "/home/ckq/anaconda3/envs/py39/bin/torchrun", line 33, in <module>
    sys.exit(load_entry_point('torch==1.13.1', 'console_scripts', 'torchrun')())
  File "/home/ckq/anaconda3/envs/py39/lib/python3.8/site-packages/torch/distributed/elastic/multiprocessing/errors/__init__.py", line 346, in wrapper
    return f(*args, **kwargs)
  File "/home/ckq/anaconda3/envs/py39/lib/python3.8/site-packages/torch/distributed/run.py", line 762, in main
    run(args)
  File "/home/ckq/anaconda3/envs/py39/lib/python3.8/site-packages/torch/distributed/run.py", line 753, in run
    elastic_launch(
  File "/home/ckq/anaconda3/envs/py39/lib/python3.8/site-packages/torch/distributed/launcher/api.py", line 132, in __call__
    return launch_agent(self._config, self._entrypoint, list(args))
  File "/home/ckq/anaconda3/envs/py39/lib/python3.8/site-packages/torch/distributed/launcher/api.py", line 246, in launch_agent
    raise ChildFailedError(
torch.distributed.elastic.multiprocessing.errors.ChildFailedError: 
============================================================
/train/train_mem.py FAILED
------------------------------------------------------------
Failures:
[1]:
  time      : 2023-04-16_17:03:22
  host      : zkyd
  rank      : 1 (local_rank: 1)
  exitcode  : 2 (pid: 2387746)
  error_file: <N/A>
  traceback : To enable traceback see: https://pytorch.org/docs/stable/elastic/errors.html
[2]:
  time      : 2023-04-16_17:03:22
  host      : zkyd
  rank      : 2 (local_rank: 2)
  exitcode  : 2 (pid: 2387747)
  error_file: <N/A>
  traceback : To enable traceback see: https://pytorch.org/docs/stable/elastic/errors.html
[3]:
  time      : 2023-04-16_17:03:22
  host      : zkyd
  rank      : 3 (local_rank: 3)
  exitcode  : 2 (pid: 2387749)
  error_file: <N/A>
  traceback : To enable traceback see: https://pytorch.org/docs/stable/elastic/errors.html
[4]:
  time      : 2023-04-16_17:03:22
  host      : zkyd
  rank      : 4 (local_rank: 4)
  exitcode  : 2 (pid: 2387753)
  error_file: <N/A>
  traceback : To enable traceback see: https://pytorch.org/docs/stable/elastic/errors.html
[5]:
  time      : 2023-04-16_17:03:22
  host      : zkyd
  rank      : 5 (local_rank: 5)
  exitcode  : 2 (pid: 2387757)
  error_file: <N/A>
  traceback : To enable traceback see: https://pytorch.org/docs/stable/elastic/errors.html
------------------------------------------------------------
Root Cause (first observed failure):
[0]:
  time      : 2023-04-16_17:03:22
  host      : zkyd
  rank      : 0 (local_rank: 0)
  exitcode  : 2 (pid: 2387745)
  error_file: <N/A>
  traceback : To enable traceback see: https://pytorch.org/docs/stable/elastic/errors.html
============================================================
